<?xml version="1.0"?>

<robot
  name="link1_urdf" xmlns:xacro="http://ros.org/wiki/xacro">

  <link name="world"/>

  <joint name="base_joint" type="fixed">
    <parent link="world"/>
    <child link="base_link"/>
    <origin rpy="0 0 0" xyz="0 0 0"/>
    </joint>
    
  <link
    name="base_link">
    <inertial>
      <origin
        xyz="0.00049737 0.00026123 0.0072038"
        rpy="0 0 0" />
      <mass
        value="6.9112" />
      <inertia
        ixx="0.046617"
        ixy="0.00010077"
        ixz="5.1488E-08"
        iyy="0.046482"
        iyz="-1.4461E-07"
        izz="0.092984" />
    </inertial>
    <visual>
      <origin
        xyz="0 0 0"
        rpy="0 0 0" />
      <geometry>
        <mesh
          filename="$(find gazebo_1_sim)/meshes/base_link.STL" />
      </geometry>
      <material
        name="">
        <color
          rgba="0.77647 0.75686 0.73725 1" />
      </material>
    </visual>
    <collision>
      <origin
        xyz="0 0 0"
        rpy="0 0 0" />
      <geometry>
        <mesh
          filename="$(find gazebo_1_sim)/meshes/base_link.STL" />
      </geometry>
    </collision>
  </link>
  <link
    name="Link_1">
    <inertial>
      <origin
        xyz="1.4551E-05 -0.0043711 0.069929"
        rpy="0 0 0" />
      <mass
        value="1.4053" />
      <inertia
        ixx="0.0017174"
        ixy="6.6784E-08"
        ixz="3.5551E-07"
        iyy="0.002626"
        iyz="6.0024E-06"
        izz="0.0017063" />
    </inertial>
    <visual>
      <origin
        xyz="0 0 0"
        rpy="0 0 0" />
      <geometry>
        <mesh
          filename="$(find gazebo_1_sim)/meshes/Link_1.STL" />
      </geometry>
      <material
        name="">
        <color
          rgba="0 0 0 1" />
      </material>
    </visual>
    <collision>
      <origin
        xyz="0 0 0"
        rpy="0 0 0" />
      <geometry>
        <mesh
          filename="$(find gazebo_1_sim)/meshes/Link_1.STL" />
      </geometry>
    </collision>
  </link>
  <joint
    name="joint_1"
    type="continuous">
    <origin
      xyz="0 0 0.05"
      rpy="0 0 3.1416" />
    <parent
      link="base_link" />
    <child
      link="Link_1" />
    <axis
      xyz="0 0 -1" />
    <limit
      lower="0"
      upper="3.14"
      effort="0"
      velocity="0" />
  </joint>
  
  <ros2_control name="GazeboSystem" type="system">
    <hardware>
      <plugin>gazebo_ros2_control/GazeboSystem</plugin>
    </hardware>
    <joint name="joint_1">
      <command_interface name="position">
      </command_interface>
      <state_interface name="position">
        <param name="initial_value">0</param>
      </state_interface>
      <state_interface name="velocity"/>
      <state_interface name="effort"/>
    </joint>

  </ros2_control>

  <gazebo>
    <plugin filename="libgazebo_ros2_control.so" name="gazebo_ros2_control">
      <parameters>$(find gazebo_1_sim)/config/joint_controller.yaml</parameters>
    </plugin>
  </gazebo>

</robot>